Workbook

Sheet Budget
B2: Budget
B4: Income: | C4: Monthly | D4: Annualized
B5: =Income!A2 -> Primary Job | C5: 8000 | D5: =C5*12 -> 96000
B6: =Income!A4 -> Loan / Grant | C6: 0 | D6: =C6*12 -> 0
B7: =Income!A5 -> Gift | C7: 0 | D7: =C7*12 -> 0
B8: =Income!A6 -> Investment Income | C8: 0 | D8: =C8*12 -> 0
B9: =Income!A7 -> Rental Income | C9: 0 | D9: =C9*12 -> 0
B10: =Income!A8 -> Secondary Income | C10: 0 | D10: =C10*12 -> 0
B11: =Income!A9 -> Allowance | C11: 0 | D11: =C11*12 -> 0
B12: =Income!A10 -> Child Support / Alimony | C12: 0 | D12: =C12*12 -> 0
B13: Total Income: | C13: =SUM(C5:C12) -> 8000 | D13: =SUM(D5:D12) -> 96000
B16: Fixed Expenses: | C16: Monthly | D16: Annualized
B17: ='Fixed Expenses'!A2 -> Housing | C17: 1100 | D17: =C17*12 -> 13200
B18: ='Fixed Expenses'!A3 -> Gas | C18: 120 | D18: =C18*12 -> 1440
B19: ='Fixed Expenses'!A4 -> Phone | C19: 50 | D19: =C19*12 -> 600
B20: ='Fixed Expenses'!A5 -> Car | C20: 300 | D20: =C20*12 -> 3600
B21: ='Fixed Expenses'!A6 -> Internet | C21: 60 | D21: =C21*12 -> 720
B22: ='Fixed Expenses'!A7 -> Groceries | C22: 300 | D22: =C22*12 -> 3600
B23: ='Fixed Expenses'!A8 -> Health Insurance | C23: 150 | D23: =C23*12 -> 1800
B24: ='Fixed Expenses'!A9 -> Car Insurance | C24: 110 | D24: =C24*12 -> 1320
B25: ='Fixed Expenses'!A10 -> Utilities | C25: 130 | D25: =C25*12 -> 1560
B26: ='Fixed Expenses'!A11 -> Student Loan | C26: 0 | D26: =C26*12 -> 0
B27: ='Fixed Expenses'!A12 -> Taxes | C27: 1276 | D27: =C27*12 -> 15312
B28: ='Fixed Expenses'!A13 -> Property Taxes | C28: 0 | D28: =C28*12 -> 0
... B30: ='Fixed Expenses'!A15 -> Retirement | C30: 290 | D30: =C30*12 -> 3480
B31: ='Fixed Expenses'!A16 -> 0 | D31: =C31*12 -> 0
B32: ='Fixed Expenses'!A17 -> 0 | D32: =C32*12 -> 0
B33: ='Fixed Expenses'!A18 -> 0 | D33: =C33*12 -> 0
B34: ='Fixed Expenses'!A19 -> 0 | D34: =C34*12 -> 0
B35: Total Fixed Expenses: | C35: =SUM(C17:C34) -> 3886 | D35: =SUM(D17:D34) -> 46632
B38: Variable Expenses: | C38: Monthly | D38: Annualized
B39: ='Variable Expenses'!A2 -> Subscriptions - Netflix | C39: 15 | D39: =C39*12 -> 180
B40: ='Variable Expenses'!A3 -> Videogames | C40: 10 | D40: =C40*12 -> 120
B41: ='Variable Expenses'!A4 -> Gym | C41: 20 | D41: =C41*12 -> 240
B42: ='Variable Expenses'!A5 -> Golf | C42: 0 | D42: =C42*12 -> 0
B43: ='Variable Expenses'!A6 -> Animals | C43: 0 | D43: =C43*12 -> 0
B44: ='Variable Expenses'!A7 -> Going Out | C44: 30 | D44: =C44*12 -> 360
B45: ='Variable Expenses'!A8 -> Going Out to Eat | C45: 20 | D45: =C45*12 -> 240
B46: ='Variable Expenses'!A9 -> Clothes | C46: 30 | D46: =C46*12 -> 360
B47: ='Variable Expenses'!A10 -> Nails Done / Hair Done | C47: 15 | D47: =C47*12 -> 180
...

Sheet Income
A1: Income - Examples
A2: Primary Job
A3: Bonus
A4: Loan / Grant
A5: Gift
A6: Investment Income
A7: Rental Income
A8: Secondary Income
A9: Allowance
A10: Child Support / Alimony

Sheet Fixed Expenses
A1: Fixed Expenses - Examples
A2: Housing
A3: Gas
A4: Phone
A5: Car
A6: Internet
A7: Groceries
A8: Health Insurance
A9: Car Insurance
A10: Utilities
A11: Student Loan
A12: Taxes
... A15: Retirement

Sheet Variable Expenses
A1: Variable Expenses - Examples
A2: Subscriptions - Netflix
A3: Videogames
A4: Gym
A5: Golf
A6: Animals
A7: Going Out
A8: Going Out to Eat
A9: Clothes
A10: Nails Done / Hair Done
A11: Make-Up
A12: Coffee
... A19: Gifts
